Workbook

Sheet Read Me & Sources
A1: Cross-hedging castor meal with NCDEX castor seed futures: Read Me & Sources
A3: ASSIGNMENT
A4: Hedge a castor meal price exposure (Asset A) with NCDEX castor seed futures (Asset B), because no castor meal futures contract exists. Use about three years of daily data; estimate the optimal hedge; measure in-sample hedge effectiveness; test it out of sample; deal with futures roll and data problems using the two course papers.
A6: DATA SOURCES
A7: Item | B7: Publisher | C7: Source | D7: Field used | E7: Unit
A8: Asset A: castor meal spot | B8: The Solvent Extractors' Association of India (SEA) | C8: https://seaofindia.com/seaquotes/ (one page per day; URLs in Spot Data) | D8: Castormeal Ext (FOR) (Bulk) (Ex-Kandla) | E8: Rs/MT
A9: Asset B: castor seed futures | B9: National Commodity & Derivatives Exchange (NCDEX) | C9: https://www.ncdex.com/markets/bhavcopy (daily ZIP, FO_DDMMYY_FINAL.csv) | D9: CASTOR contracts: close, volume, open interest, expiry | E9: Rs/quintal; MT
A10: CASTOR contract rules | B10: NCDEX | C10: https://www.ncdex.com/public/uploads/downloads/Contract%20Specifications%20Castor%20Futures%20Contract_31082026_1788157717.pdf | D10: Expiry 20th (or previous trading day); compulsory delivery; tender period last 3 trading days
A11: Pre-expiry margin (context) | B11: NCCL (NCDEX clearing) | C11: https://www.ncdex.com/public/uploads/circulars/Pre_Expiry_Margin_Castor_04082022_1659619001.pdf | D11: Margin over last 7 trading days (2022 circular)
A12: Method papers | B12: Course material | C12: paper_1.pdf: Continuous Contracts Explained; paper_2.pdf: Buyukkara, Kucukozmen & Uysal (2022), Borsa Istanbul Review 22-1, 92-102
A14: SAMPLE COVERAGE (live formulas)
A15: Spot quotes used: first / last / count | C15: =TEXT(_xlfn.MINIFS('Spot Data'!$A$5:$A$651,'Spot Data'!$H$5:$H$651,"YES"),"dd mmm yyyy")&" to "&TEXT(_xlfn.MAXIFS('Spot Data'!$A$5:$A$651,'Spot Data'!$H$5:$H$651,"YES"),"dd mmm yyyy")&" ("&COUNTIF('Spot Data'!$H$5:$H$651,"YES")&" quotes)" -> 25 Sep 2023 to 28 Sep 2026 (546 quotes)
A16: Futures trading days: first / last / count | C16: =TEXT(MIN('Roll Schedule'!A47:A790),"dd mmm yyyy")&" to "&TEXT(MAX('Roll Schedule'!A47:A790),"dd mmm yyyy")&" ("&COUNT('Roll Schedule'!A47:A790)&" days)" -> 25 Sep 2023 to 28 Sep 2026 (744 days)
A17: Common price dates (NCDEX trading day with a used SEA quote) | C17: =TEXT(_xlfn.MINIFS('Spot Data'!$A$5:$A$651,'Spot Data'!$H$5:$H$651,"YES",'Spot Data'!$I$5:$I$651,TRUE()),"dd mmm yyyy")&" to "&TEXT(_xlfn.MAXIFS('Spot Data'!$A$5:$A$651,'Spot Data'!$H$5:$H$651,"YES",'Spot Data'!$I$5:$I$651,TRUE()),"dd mmm yyyy")&" ("&COUNTIFS('Spot Data'!$H$5:$H$651,"YES",'Spot Data'!$I$5:$I$651,TRUE())&" dates)" -> 25 Sep 2023 to 28 Sep 2026 (535 dates)
A18: Return dates: first / last / count | C18: =TEXT(MIN('Daily Analysis'!A5:A500),"dd mmm yyyy")&" to "&TEXT(MAX('Daily Analysis'!A5:A500),"dd mmm yyyy")&" ("&COUNT('Daily Analysis'!H5:H500)&" returns)" -> 26 Sep 2023 to 28 Sep 2026 (496 returns)
A19: In-sample returns | C19: =TEXT('Results & Charts'!D18,"dd mmm yyyy")&" to "&TEXT('Results & Charts'!E18,"dd mmm yyyy")&" ("&'Results & Charts'!F18&")" -> 26 Sep 2023 to 26 Sep 2025 (275)
A20: Out-of-sample returns | C20: =TEXT('Results & Charts'!D19,"dd mmm yyyy")&" to "&TEXT('Results & Charts'!E19,"dd mmm yyyy")&" ("&'Results & Charts'!F19&")" -> 01 Oct 2025 to 28 Sep 2026 (221)
A21: Calendar coverage is three full years of returns (26 Sep 2023 to 28 Sep 2026), BUT SEA published no castor meal quote from 27 Apr 2024 to 3 Dec 2024 (castor meal marked NQ May-Sep 2024; almost no posts Oct-Nov 2024). No returns exist for that gap; nothing is filled. SEA quotes on non-NCDEX days are listed but not used.
A23: METHOD AND ITS BASIS
A24: Step | B24: What is done | C24: Basis | D24: Classification | E24: Where
A25: Contracts kept separate | B25: Every CASTOR contract kept by expiry; continuous series built by an explicit rule | C25: CCE p.1 | D25: Prescribed in paper | E25: Futures Data, Roll Schedule
A26: Roll signal | B26: Next-month open interest larger than held month's | C26: CCE p.2 ('volume and/or open interest') | D26: Prescribed (OI chosen over volume: adaptation) | E26: Roll Schedule E-H
A27: Execution timing | B27: Signal read from the day's published file, acted on at the next close | C27: Not specified in either paper | D27: Project adaptation (removes look-ahead) | E27: Roll Schedule C
A28: Backstop | B28: Forced roll when 7 NCDEX trading days remain | C28: CCE p.1-2 notice-day argument; NCDEX tender period; NCCL pre-expiry margin | D28: Project adaptation | E28: Roll Schedule G4
A29: Roll gap and back-adjustment | B29: Gap = new close - old close on roll day; back-adjusted = stitched + later gaps | C29: CCE p.7-8 | D29: Prescribed in paper | E29: Roll Schedule J-N
A30: Hedge returns | B30: LN return of the contract actually held, never across two contracts | C30: BKU eq. (1)-(2); CCE p.9 'trading reality' | D30: Prescribed returns, applied per held contract (adaptation) | E30: Roll Schedule O; Daily Analysis I
A31: OLS hedge ratio | B31: SLOPE of rA on rF, in-sample only | C31: BKU eq. (3), p.96 | D31: Prescribed | E31: Results Table 1
A32: Naive hedge | B32: h = 1 | C32: BKU p.95 | D32: Prescribed | E32: Results Table 2
A33: Dynamic hedge | B33: Diagonal VECH GARCH(1,1), h_t = H12/H22 | C33: BKU eq. (4)-(8), p.96 | D33: Prescribed (estimated in-sample, fixed out-of-sample: adaptation) | E33: Results Table 4
A34: Hedge effectiveness | B34: 1 - Var(hedged)/Var(unhedged) | C34: BKU eq. (11)-(13), p.97 | D34: Prescribed (eq. 10 printed sign inconsistent with eq. 12; eq. 12 used) | E34: Results Table 2
A35: Out-of-sample test | B35: Chronological split at 30 Sep 2025 | C35: Assignment brief (paper uses sub-periods, not out-of-sample) | D35: Additional to papers | E35: Results Table 2
... A37: Roll comparison | B37: Five rules on identical dates | C37: CCE p.2 (compare roll schedules) | D37: Prescribed idea; rules are adaptations | E37: Results Table 6
A39: CCE = Continuous Contracts Explained (paper_1.pdf, PDF page numbers). BKU = Buyukkara, Kucukozmen & Uysal (2022) (journal page numbers).
A41: DEFINITIONS AND TREATMENT OF DATA
A42: - Return pair: two consecutive NCDEX trading days, both with a used SEA quote. Weekends and holidays are skipped naturally (a Monday return spans Friday-Monday).
A43: - Missing SEA quote (NQ, row absent, excluded post): no return is formed for the pairs touching that date. Nothing is interpolated or carried forward.
A44: - Unchanged SEA quote: a genuine zero return; kept.
A45: - SEA quote on a non-NCDEX day: listed in Spot Data; not used.
A46: - Futures price: NCDEX closing price. Settlement price is absent from files before 8 Jul 2024, so close is used throughout.
A47: - Colour key: blue = source value or Python output; black = formula; green = link; yellow = input.
...

Sheet Spot Data
A1: Spot Data: castor meal quotes published by The Solvent Extractors' Association of India (SEA). NOT NCDEX data.
A2: Quote: 'Castormeal Ext (FOR) (Bulk) (Ex-Kandla)', Rs per metric tonne. One SEA post per day; every post in the window is listed, including excluded ones. Values unchanged from the source.
A4: Quote date | B4: Post title | C4: Published (IST) | D4: Castor meal cell as published | E4: Price (Rs/MT) | F4: Date rule | G4: Status | H4: Used in analysis | I4: NCDEX trading day? | J4: Live check | K4: Source URL
A5: 45194 | B5: 25th September 23 | C5: 2023-09-25T17:32:41 | D5: Rs./ MT 9575 | E5: 9575 | F5: A_title | G5: OK | H5: =IF(G5="OK","YES","no") -> YES | I5: =COUNTIF('Roll Schedule'!$A$47:$A$790,A5)>0 -> TRUE | J5: fetched 29 Sep 2026 (new post) | K5: https://seaofindia.com/seaquotes/25th-september-23/
A6: 45195 | B6: 26th September 23 | C6: 2023-09-26T17:23:30 | D6: Rs./ MT 9500 | E6: 9500 | F6: A_title | G6: OK | H6: =IF(G6="OK","YES","no") -> YES | I6: =COUNTIF('Roll Schedule'!$A$47:$A$790,A6)>0 -> TRUE | J6: fetched 29 Sep 2026 (new post) | K6: https://seaofindia.com/seaquotes/26th-september-23/
A7: 45196 | B7: 28th September 2023 | C7: 2023-09-27T16:59:38 | D7: Rs./ MT 9450 | E7: 9450 | F7: B_pub_title_implausible | G7: EXCLUDED: uncertain publication date | H7: =IF(G7="OK","YES","no") -> no | I7: =COUNTIF('Roll Schedule'!$A$47:$A$790,A7)>0 -> TRUE | J7: fetched 29 Sep 2026 (new post) | K7: https://seaofindia.com/seaquotes/28th-september-2023/
A8: 45198 | B8: 29th September 23 | C8: 2023-09-29T17:34:34 | D8: Rs./ MT 9450 | E8: 9450 | F8: A_title | G8: OK | H8: =IF(G8="OK","YES","no") -> YES | I8: =COUNTIF('Roll Schedule'!$A$47:$A$790,A8)>0 -> TRUE | J8: fetched 29 Sep 2026 (new post) | K8: https://seaofindia.com/seaquotes/29th-september-23/
A9: 45202 | B9: 3rd October 23 | C9: 2023-10-03T17:25:44 | D9: Rs./ MT 9350 | E9: 9350 | F9: A_title | G9: OK | H9: =IF(G9="OK","YES","no") -> YES | I9: =COUNTIF('Roll Schedule'!$A$47:$A$790,A9)>0 -> TRUE | J9: matches live page 29 Sep 2026 | K9: https://seaofindia.com/seaquotes/3rd-october-23/
A10: 45203 | B10: 4th October 23 | C10: 2023-10-04T17:33:09 | D10: Rs./ MT 9150 | E10: 9150 | F10: A_title | G10: OK | H10: =IF(G10="OK","YES","no") -> YES | I10: =COUNTIF('Roll Schedule'!$A$47:$A$790,A10)>0 -> TRUE | J10: matches live page 29 Sep 2026 | K10: https://seaofindia.com/seaquotes/4th-october-23/
A11: 45204 | B11: 5th October 23 | C11: 2023-10-05T17:17:31 | D11: Rs./ MT 9000 | E11: 9000 | F11: A_title | G11: OK | H11: =IF(G11="OK","YES","no") -> YES | I11: =COUNTIF('Roll Schedule'!$A$47:$A$790,A11)>0 -> TRUE | J11: matches live page 29 Sep 2026 | K11: https://seaofindia.com/seaquotes/5th-october-23/
A12: 45205 | B12: 6th October 23 | C12: 2023-10-06T17:43:33 | D12: Rs./ MT 8950 | E12: 8950 | F12: A_title | G12: OK | H12: =IF(G12="OK","YES","no") -> YES | I12: =COUNTIF('Roll Schedule'!$A$47:$A$790,A12)>0 -> TRUE | J12: matches live page 29 Sep 2026 | K12: https://seaofindia.com/seaquotes/6th-october-23/
A13: 45208 | B13: 9th October 23 | C13: 2023-10-09T17:28:05 | D13: Rs./ MT 8875 | E13: 8875 | F13: A_title | G13: OK | H13: =IF(G13="OK","YES","no") -> YES | I13: =COUNTIF('Roll Schedule'!$A$47:$A$790,A13)>0 -> TRUE | J13: matches live page 29 Sep 2026 | K13: https://seaofindia.com/seaquotes/9th-october-23/
A14: 45209 | B14: 10th October 23 | C14: 2023-10-10T17:25:14 | D14: Rs./ MT 8950 | E14: 8950 | F14: A_title | G14: OK | H14: =IF(G14="OK","YES","no") -> YES | I14: =COUNTIF('Roll Schedule'!$A$47:$A$790,A14)>0 -> TRUE | J14: matches live page 29 Sep 2026 | K14: https://seaofindia.com/seaquotes/10th-october-23/
A15: 45210 | B15: 11th October 23 | C15: 2023-10-11T17:25:49 | D15: Rs./ MT 8800 | E15: 8800 | F15: A_title | G15: OK | H15: =IF(G15="OK","YES","no") -> YES | I15: =COUNTIF('Roll Schedule'!$A$47:$A$790,A15)>0 -> TRUE | J15: matches live page 29 Sep 2026 | K15: https://seaofindia.com/seaquotes/11th-october-23/
A16: 45211 | B16: 12th October 23 | C16: 2023-10-12T17:35:08 | D16: Rs./ MT 8700 | E16: 8700 | F16: A_title | G16: OK | H16: =IF(G16="OK","YES","no") -> YES | I16: =COUNTIF('Roll Schedule'!$A$47:$A$790,A16)>0 -> TRUE | J16: matches live page 29 Sep 2026 | K16: https://seaofindia.com/seaquotes/12th-october-23/
... A29: 45232 | B29: 2nd Nov 23 | C29: 2023-11-02T17:33:07 | D29: Rs./ MT 7800 | E29: 7800 | F29: A_title | G29: OK | H29: =IF(G29="OK","YES","no") -> YES | I29: =COUNTIF('Roll Schedule'!$A$47:$A$790,A29)>0 -> TRUE | J29: matches live page 29 Sep 2026 | K29: https://seaofindia.com/seaquotes/2nd-nov-23/
A30: 45233 | C30: 2023-11-03T17:26:11 | D30: Rs./ M T 7950 | E30: 7950 | F30: D_pub_no_usable_title | G30: EXCLUDED: uncertain publication date | H30: =IF(G30="OK","YES","no") -> no | I30: =COUNTIF('Roll Schedule'!$A$47:$A$790,A30)>0 -> TRUE | J30: matches live page 29 Sep 2026 | K30: https://seaofindia.com/seaquotes/11726-2/
A31: 45237 | B31: 7th November 23 | C31: 2023-11-07T17:19:39 | D31: Rs./ MT 7950 | E31: 7950 | F31: A_title | G31: OK | H31: =IF(G31="OK","YES","no") -> YES | I31: =COUNTIF('Roll Schedule'!$A$47:$A$790,A31)>0 -> TRUE | J31: matches live page 29 Sep 2026 | K31: https://seaofindia.com/seaquotes/7th-november-23/
A32: 45239 | B32: 9th November 23 | C32: 2023-11-09T17:19:49 | D32: Rs./ MT 7950 | E32: 7950 | F32: A_title | G32: OK | H32: =IF(G32="OK","YES","no") -> YES | I32: =COUNTIF('Roll Schedule'!$A$47:$A$790,A32)>0 -> TRUE | J32: matches live page 29 Sep 2026 | K32: https://seaofindia.com/seaquotes/9th-november-23/
A33: 45240 | C33: 2023-11-10T17:30:39 | D33: Rs./ MT 7950 | E33: 7950 | F33: D_pub_no_usable_title | G33: EXCLUDED: uncertain publication date | H33: =IF(G33="OK","YES","no") -> no | I33: =COUNTIF('Roll Schedule'!$A$47:$A$790,A33)>0 -> TRUE | J33: matches live page 29 Sep 2026 | K33: https://seaofindia.com/seaquotes/11740-2/
A34: 45246 | B34: 16th November 23 | C34: 2023-11-16T17:31:27 | D34: Rs./ MT NQ | F34: A_title | G34: NQ (not quoted by SEA) | H34: =IF(G34="OK","YES","no") -> no | I34: =COUNTIF('Roll Schedule'!$A$47:$A$790,A34)>0 -> TRUE | J34: matches live page 29 Sep 2026 | K34: https://seaofindia.com/seaquotes/16th-november-23/
A35: 45247 | B35: 17th November 23 | C35: 2023-11-17T17:47:56 | D35: Rs./ MT NQ | F35: A_title | G35: NQ (not quoted by SEA) | H35: =IF(G35="OK","YES","no") -> no | I35: =COUNTIF('Roll Schedule'!$A$47:$A$790,A35)>0 -> TRUE | J35: matches live page 29 Sep 2026 | K35: https://seaofindia.com/seaquotes/17th-november-23/
A36: 45247 | B36: 17th November 23 | C36: 2023-11-17T17:49:15 | D36: Rs./ MT NQ | F36: A_title | G36: EXCLUDED: duplicate post (identical values, earlier post kept) | H36: =IF(G36="OK","YES","no") -> no | I36: =COUNTIF('Roll Schedule'!$A$47:$A$790,A36)>0 -> TRUE | J36: matches live page 29 Sep 2026 | K36: https://seaofindia.com/seaquotes/17th-november-23-2/
A37: 45250 | B37: 20th November 23 | C37: 2023-11-20T17:54:16 | D37: Rs./ MT 7950 | E37: 7950 | F37: A_title | G37: OK | H37: =IF(G37="OK","YES","no") -> YES | I37: =COUNTIF('Roll Schedule'!$A$47:$A$790,A37)>0 -> TRUE | J37: matches live page 29 Sep 2026 | K37: https://seaofindia.com/seaquotes/20th-november-23/
A38: 45251 | B38: 21st November 23 | C38: 2023-11-21T17:25:15 | D38: Rs./ MT 8400 | E38: 8400 | F38: A_title | G38: OK | H38: =IF(G38="OK","YES","no") -> YES | I38: =COUNTIF('Roll Schedule'!$A$47:$A$790,A38)>0 -> TRUE | J38: matches live page 29 Sep 2026 | K38: https://seaofindia.com/seaquotes/21st-november-23/
A39: 45252 | B39: 22nd November 23 | C39: 2023-11-22T17:26:44 | D39: Rs./ MT 8700 | E39: 8700 | F39: A_title | G39: OK | H39: =IF(G39="OK","YES","no") -> YES | I39: =COUNTIF('Roll Schedule'!$A$47:$A$790,A39)>0 -> TRUE | J39: matches live page 29 Sep 2026 | K39: https://seaofindia.com/seaquotes/22nd-november-23/
A40: 45253 | B40: 23rd November 23 | C40: 2023-11-23T17:33:47 | D40: Rs./ MT 8950 | E40: 8950 | F40: A_title | G40: OK | H40: =IF(G40="OK","YES","no") -> YES | I40: =COUNTIF('Roll Schedule'!$A$47:$A$790,A40)>0 -> TRUE | J40: matches live page 29 Sep 2026 | K40: https://seaofindia.com/seaquotes/23rd-november-23/
A41: 45254 | B41: 24thNovember 23 | C41: 2023-11-24T17:54:15 | D41: Rs./ MT 8900 | E41: 8900 | F41: A_title | G41: OK | H41: =IF(G41="OK","YES","no") -> YES | I41: =COUNTIF('Roll Schedule'!$A$47:$A$790,A41)>0 -> TRUE | J41: matches live page 29 Sep 2026 | K41: https://seaofindia.com/seaquotes/24thnovember-23/
A42: 45258 | B42: 28th November 23 | C42: 2023-11-28T17:00:57 | D42: Rs./ MT 9050 | E42: 9050 | F42: A_title | G42: OK | H42: =IF(G42="OK","YES","no") -> YES | I42: =COUNTIF('Roll Schedule'!$A$47:$A$790,A42)>0 -> TRUE | J42: matches live page 29 Sep 2026 | K42: https://seaofindia.com/seaquotes/28th-november-23/
A43: 45259 | B43: 29th Novembr 2023 | C43: 2023-11-29T17:15:46 | D43: Rs./ MT 9000 | E43: 9000 | F43: A_title | G43: OK | H43: =IF(G43="OK","YES","no") -> YES | I43: =COUNTIF('Roll Schedule'!$A$47:$A$790,A43)>0 -> TRUE | J43: matches live page 29 Sep 2026 | K43: https://seaofindia.com/seaquotes/29th-novembr-2023/
A44: 45260 | B44: 30th Nov 23 | C44: 2023-11-30T17:28:18 | D44: Rs./ MT 8900 | E44: 8900 | F44: A_title | G44: OK | H44: =IF(G44="OK","YES","no") -> YES | I44: =COUNTIF('Roll Schedule'!$A$47:$A$790,A44)>0 -> TRUE | J44: matches live page 29 Sep 2026 | K44: https://seaofindia.com/seaquotes/30th-nov-23/
A45: 45261 | B45: 1st Dec 23 | C45: 2023-12-01T17:54:57 | D45: Rs./ MT 8850 | E45: 8850 | F45: A_title | G45: OK | H45: =IF(G45="OK","YES","no") -> YES | I45: =COUNTIF('Roll Schedule'!$A$47:$A$790,A45)>0 -> TRUE | J45: matches live page 29 Sep 2026 | K45: https://seaofindia.com/seaquotes/1st-dec-23/
A46: 45264 | B46: 4th Dec 23 | C46: 2023-12-04T17:40:01 | D46: Rs./ MT 8750 | E46: 8750 | F46: A_title | G46: OK | H46: =IF(G46="OK","YES","no") -> YES | I46: =COUNTIF('Roll Schedule'!$A$47:$A$790,A46)>0 -> TRUE | J46: matches live page 29 Sep 2026 | K46: https://seaofindia.com/seaquotes/4th-dec-23-2/
A47: 45266 | B47: 6th Dec 23 | C47: 2023-12-06T17:35:23 | D47: Rs./ MT 8850 | E47: 8850 | F47: A_title | G47: OK | H47: =IF(G47="OK","YES","no") -> YES | I47: =COUNTIF('Roll Schedule'!$A$47:$A$790,A47)>0 -> TRUE | J47: matches live page 29 Sep 2026 | K47: https://seaofindia.com/seaquotes/6th-dec-23/
A48: 45267 | B48: 7th Dec 23 | C48: 2023-12-07T17:42:02 | D48: Rs./ MT 8650 | E48: 8650 | F48: A_title | G48: OK | H48: =IF(G48="OK","YES","no") -> YES | I48: =COUNTIF('Roll Schedule'!$A$47:$A$790,A48)>0 -> TRUE | J48: matches live page 29 Sep 2026 | K48: https://seaofindia.com/seaquotes/7th-dec-23/
... A124: 45411 | B124: 29th Jan 24 | C124: 2024-04-29T17:24:33 | D124: Rs./MT 6050 | E124: 6050 | F124: B_pub_title_implausible | G124: EXCLUDED: uncertain publication date | H124: =IF(G124="OK","YES","no") -> no | I124: =COUNTIF('Roll Schedule'!$A$47:$A$790,A124)>0 -> TRUE | J124: matches live page 29 Sep 2026 | K124: https://seaofindia.com/seaquotes/29th-jan-24-2/
A125: 45412 | B125: 30th April 24 | C125: 2024-04-30T16:55:28 | D125: (row absent) | F125: A_title | G125: NQ (not quoted by SEA) | H125: =IF(G125="OK","YES","no") -> no | I125: =COUNTIF('Roll Schedule'!$A$47:$A$790,A125)>0 -> TRUE | J125: matches live page 29 Sep 2026 | K125: https://seaofindia.com/seaquotes/30th-april-24/
A126: 45414 | B126: 2nd May 24 | C126: 2024-05-02T17:03:58 | D126: (row absent) | F126: A_title | G126: NQ (not quoted by SEA) | H126: =IF(G126="OK","YES","no") -> no | I126: =COUNTIF('Roll Schedule'!$A$47:$A$790,A126)>0 -> TRUE | J126: matches live page 29 Sep 2026 | K126: https://seaofindia.com/seaquotes/2nd-may-24/
A127: 45415 | B127: 3rd May 24 | C127: 2024-05-03T18:08:31 | D127: (row absent) | F127: A_title | G127: NQ (not quoted by SEA) | H127: =IF(G127="OK","YES","no") -> no | I127: =COUNTIF('Roll Schedule'!$A$47:$A$790,A127)>0 -> TRUE | J127: matches live page 29 Sep 2026 | K127: https://seaofindia.com/seaquotes/3rd-may-24/
A128: 45418 | B128: 6th May 24 | C128: 2024-05-06T17:11:21 | D128: (row absent) | F128: A_title | G128: NQ (not quoted by SEA) | H128: =IF(G128="OK","YES","no") -> no | I128: =COUNTIF('Roll Schedule'!$A$47:$A$790,A128)>0 -> TRUE | J128: matches live page 29 Sep 2026 | K128: https://seaofindia.com/seaquotes/6th-may-24/
...

Sheet Futures Data
A1: Futures Data: NCDEX castor seed futures (symbol CASTOR), every contract on every trading day. Source: NCDEX daily final bhavcopy.
A2: File FO_DDMMYY_FINAL.csv in each daily ZIP from https://www.ncdex.com/markets/bhavcopy, rows with Instrument Type FUTCOM. Close in Rs per quintal; volume and open interest in MT. Values unchanged.
A4: Trade date | B4: Contract expiry | C4: Close (Rs/qtl) | D4: Volume (MT) | E4: Open interest (MT) | F4: Price unit | G4: Delivery centre | H4: Source file
A5: 45194 | B5: 45219 | C5: 6176 | D5: 6820 | E5: 27755 | F5: RS/QUINTAL | G5: DEESA | H5: ncdex_bhavcopy_20230925.zip::FO_250923_FINAL.csv
A6: 45194 | B6: 45250 | C6: 6234 | D6: 3660 | E6: 10270 | F6: RS/QUINTAL | G6: DEESA | H6: ncdex_bhavcopy_20230925.zip::FO_250923_FINAL.csv
A7: 45194 | B7: 45280 | C7: 6292 | D7: 0 | E7: 120 | F7: RS/QUINTAL | G7: DEESA | H7: ncdex_bhavcopy_20230925.zip::FO_250923_FINAL.csv
A8: 45194 | B8: 45310 | C8: 6350 | D8: 0 | E8: 0 | F8: RS/QUINTAL | G8: DEESA | H8: ncdex_bhavcopy_20230925.zip::FO_250923_FINAL.csv
A9: 45195 | B9: 45219 | C9: 6155 | D9: 4340 | E9: 26860 | F9: RS/QUINTAL | G9: DEESA | H9: ncdex_bhavcopy_20230926.zip::FO_260923_FINAL.csv
A10: 45195 | B10: 45250 | C10: 6225 | D10: 2400 | E10: 11415 | F10: RS/QUINTAL | G10: DEESA | H10: ncdex_bhavcopy_20230926.zip::FO_260923_FINAL.csv
A11: 45195 | B11: 45280 | C11: 6295 | D11: 0 | E11: 120 | F11: RS/QUINTAL | G11: DEESA | H11: ncdex_bhavcopy_20230926.zip::FO_260923_FINAL.csv
A12: 45195 | B12: 45310 | C12: 6365 | D12: 0 | E12: 0 | F12: RS/QUINTAL | G12: DEESA | H12: ncdex_bhavcopy_20230926.zip::FO_260923_FINAL.csv
A13: 45196 | B13: 45219 | C13: 6164 | D13: 8775 | E13: 23975 | F13: RS/QUINTAL | G13: DEESA | H13: ncdex_bhavcopy_20230927.zip::FO_270923_FINAL.csv
A14: 45196 | B14: 45250 | C14: 6232 | D14: 5465 | E14: 15220 | F14: RS/QUINTAL | G14: DEESA | H14: ncdex_bhavcopy_20230927.zip::FO_270923_FINAL.csv
A15: 45196 | B15: 45280 | C15: 6300 | D15: 40 | E15: 125 | F15: RS/QUINTAL | G15: DEESA | H15: ncdex_bhavcopy_20230927.zip::FO_270923_FINAL.csv
A16: 45196 | B16: 45310 | C16: 6368 | D16: 0 | E16: 0 | F16: RS/QUINTAL | G16: DEESA | H16: ncdex_bhavcopy_20230927.zip::FO_270923_FINAL.csv
... A3471: 46293 | B3471: 46407 | C3471: 8105 | D3471: 0 | E3471: 0 | F3471: RS/QUINTAL | G3471: DEESA | H3471: ncdex_bhavcopy_20260928.zip::FO_280926_FINAL.csv

Sheet Roll Schedule
A1: Roll Schedule: which CASTOR contract is held each day, and every roll
A2: Rule: switch to the next contract at the close of day t if EITHER (a) at the close of day t-1 the next contract's open interest was larger than the held contract's (read from the published t-1 file, so acted on one day later) OR (b) only the backstop number of NCDEX trading days remain to the held contract's expiry (a calendar rule known in advance).
A3: Basis: Continuous Contracts Explained p.2 (rolling on open interest) and p.1 (avoid the delivery/notice period); NCDEX CASTOR specification (tender period = last 3 trading days). The one-day lag and the backstop are project adaptations.
A4: Backstop: trading days left at which the switch is forced | G4: 7
A5: Last trading day in the data | G5: =MAX(A47:A790) -> 46293
A7: Roll # | B7: Signal observed at close of | C7: Switch at close of | D7: Reason | E7: Old contract (expiry) | F7: New contract (expiry) | G7: Trading days left on old at switch | H7: OI old contract (MT) at signal date (backstop: switch date) | I7: OI new contract (MT), same date | J7: Old close at switch (Rs/qtl) | K7: New close at switch (Rs/qtl) | L7: Roll gap (new - old) | M7: Gap % | N7: First return on new contract
A8: 1 | B8: =IF(H52,A52,A53) -> 45202 | C8: =A53 -> 45203 | D8: =IF(H52,"OI signal: next-month OI > held OI at previous close","Calendar backstop: "&D53&" trading days left") -> OI signal: next-month OI > held OI at previous close | E8: =B53 -> 45219 | F8: =C53 -> 45250 | G8: =D53 -> 12 | H8: =IF(H52,E52,SUMIFS('Futures Data'!$E$5:$E$3471,'Futures Data'!$A$5:$A$3471,A53,'Futures Data'!$B$5:$B$3471,B53)) -> 18280 | I8: =IF(H52,G52,E53) -> 19645 | J8: =J53 -> 6135 | K8: =K53 -> 6193 | L8: =L53 -> 58 | M8: =L53/J53 -> 0.0094539527 | N8: =A54 -> 45204
A9: 2 | B9: =IF(H77,A77,A78) -> 45239 | C9: =A78 -> 45239 | D9: =IF(H77,"OI signal: next-month OI > held OI at previous close","Calendar backstop: "&D78&" trading days left") -> Calendar backstop: 7 trading days left | E9: =B78 -> 45250 | F9: =C78 -> 45280 | G9: =D78 -> 7 | H9: =IF(H77,E77,SUMIFS('Futures Data'!$E$5:$E$3471,'Futures Data'!$A$5:$A$3471,A78,'Futures Data'!$B$5:$B$3471,B78)) -> 20495 | I9: =IF(H77,G77,E78) -> 15600 | J9: =J78 -> 5953 | K9: =K78 -> 5873 | L9: =L78 -> -80 | M9: =L78/J78 -> -0.013438602 | N9: =A79 -> 45240
A10: 3 | B10: =IF(H94,A94,A95) -> 45264 | C10: =A95 -> 45265 | D10: =IF(H94,"OI signal: next-month OI > held OI at previous close","Calendar backstop: "&D95&" trading days left") -> OI signal: next-month OI > held OI at previous close | E10: =B95 -> 45280 | F10: =C95 -> 45310 | G10: =D95 -> 11 | H10: =IF(H94,E94,SUMIFS('Futures Data'!$E$5:$E$3471,'Futures Data'!$A$5:$A$3471,A95,'Futures Data'!$B$5:$B$3471,B95)) -> 10310 | I10: =IF(H94,G94,E95) -> 12010 | J10: =J95 -> 5880 | K10: =K95 -> 5925 | L10: =L95 -> 45 | M10: =L95/J95 -> 0.0076530612 | N10: =A96 -> 45266
A11: 4 | B11: =IF(H113,A113,A114) -> 45292 | C11: =A114 -> 45293 | D11: =IF(H113,"OI signal: next-month OI > held OI at previous close","Calendar backstop: "&D114&" trading days left") -> OI signal: next-month OI > held OI at previous close | E11: =B114 -> 45310 | F11: =C114 -> 45342 | G11: =D114 -> 13 | H11: =IF(H113,E113,SUMIFS('Futures Data'!$E$5:$E$3471,'Futures Data'!$A$5:$A$3471,A114,'Futures Data'!$B$5:$B$3471,B114)) -> 14005 | I11: =IF(H113,G113,E114) -> 16060 | J11: =J114 -> 5670 | K11: =K114 -> 5708 | L11: =L114 -> 38 | M11: =L114/J114 -> 0.00670194 | N11: =A115 -> 45294
A12: 5 | B12: =IF(H139,A139,A140) -> 45330 | C12: =A140 -> 45331 | D12: =IF(H139,"OI signal: next-month OI > held OI at previous close","Calendar backstop: "&D140&" trading days left") -> OI signal: next-month OI > held OI at previous close | E12: =B140 -> 45342 | F12: =C140 -> 45371 | G12: =D140 -> 7 | H12: =IF(H139,E139,SUMIFS('Futures Data'!$E$5:$E$3471,'Futures Data'!$A$5:$A$3471,A140,'Futures Data'!$B$5:$B$3471,B140)) -> 14835 | I12: =IF(H139,G139,E140) -> 15515 | J12: =J140 -> 5773 | K12: =K140 -> 5610 | L12: =L140 -> -163 | M12: =L140/J140 -> -0.028234887 | N12: =A141 -> 45334
A13: 6 | B13: =IF(H147,A147,A148) -> 45342 | C13: =A148 -> 45343 | D13: =IF(H147,"OI signal: next-month OI > held OI at previous close","Calendar backstop: "&D148&" trading days left") -> OI signal: next-month OI > held OI at previous close | E13: =B148 -> 45371 | F13: =C148 -> 45401 | G13: =D148 -> 19 | H13: =IF(H147,E147,SUMIFS('Futures Data'!$E$5:$E$3471,'Futures Data'!$A$5:$A$3471,A148,'Futures Data'!$B$5:$B$3471,B148)) -> 18545 | I13: =IF(H147,G147,E148) -> 21670 | J13: =J148 -> 5759 | K13: =K148 -> 5840 | L13: =L148 -> 81 | M13: =L148/J148 -> 0.014064942 | N13: =A149 -> 45344
A14: 7 | B14: =IF(H177,A177,A178) -> 45390 | C14: =A178 -> 45390 | D14: =IF(H177,"OI signal: next-month OI > held OI at previous close","Calendar backstop: "&D178&" trading days left") -> Calendar backstop: 7 trading days left | E14: =B178 -> 45401 | F14: =C178 -> 45432 | G14: =D178 -> 7 | H14: =IF(H177,E177,SUMIFS('Futures Data'!$E$5:$E$3471,'Futures Data'!$A$5:$A$3471,A178,'Futures Data'!$B$5:$B$3471,B178)) -> 23950 | I14: =IF(H177,G177,E178) -> 11970 | J14: =J178 -> 5931 | K14: =K178 -> 5895 | L14: =L178 -> -36 | M14: =L178/J178 -> -0.0060698027 | N14: =A179 -> 45391
A15: 8 | B15: =IF(H194,A194,A195) -> 45415 | C15: =A195 -> 45418 | D15: =IF(H194,"OI signal: next-month OI > held OI at previous close","Calendar backstop: "&D195&" trading days left") -> OI signal: next-month OI > held OI at previous close | E15: =B195 -> 45432 | F15: =C195 -> 45463 | G15: =D195 -> 9 | H15: =IF(H194,E194,SUMIFS('Futures Data'!$E$5:$E$3471,'Futures Data'!$A$5:$A$3471,A195,'Futures Data'!$B$5:$B$3471,B195)) -> 13380 | I15: =IF(H194,G194,E195) -> 15675 | J15: =J195 -> 5590 | K15: =K195 -> 5674 | L15: =L195 -> 84 | M15: =L195/J195 -> 0.015026834 | N15: =A196 -> 45419
A16: 9 | B16: =IF(H215,A215,A216) -> 45447 | C16: =A216 -> 45448 | D16: =IF(H215,"OI signal: next-month OI > held OI at previous close","Calendar backstop: "&D216&" trading days left") -> OI signal: next-month OI > held OI at previous close | E16: =B216 -> 45463 | F16: =C216 -> 45492 | G16: =D216 -> 10 | H16: =IF(H215,E215,SUMIFS('Futures Data'!$E$5:$E$3471,'Futures Data'!$A$5:$A$3471,A216,'Futures Data'!$B$5:$B$3471,B216)) -> 16785 | I16: =IF(H215,G215,E216) -> 18175 | J16: =J216 -> 5700 | K16: =K216 -> 5775 | L16: =L216 -> 75 | M16: =L216/J216 -> 0.013157895 | N16: =A217 -> 45449
A17: 10 | B17: =IF(H236,A236,A237) -> 45477 | C17: =A237 -> 45478 | D17: =IF(H236,"OI signal: next-month OI > held OI at previous close","Calendar backstop: "&D237&" trading days left") -> OI signal: next-month OI > held OI at previous close | E17: =B237 -> 45492 | F17: =C237 -> 45524 | G17: =D237 -> 9 | H17: =IF(H236,E236,SUMIFS('Futures Data'!$E$5:$E$3471,'Futures Data'!$A$5:$A$3471,A237,'Futures Data'!$B$5:$B$3471,B237)) -> 17945 | I17: =IF(H236,G236,E237) -> 20205 | J17: =J237 -> 5896 | K17: =K237 -> 5976 | L17: =L237 -> 80 | M17: =L237/J237 -> 0.013568521 | N17: =A238 -> 45481
A18: 11 | B18: =IF(H256,A256,A257) -> 45506 | C18: =A257 -> 45509 | D18: =IF(H256,"OI signal: next-month OI > held OI at previous close","Calendar backstop: "&D257&" trading days left") -> OI signal: next-month OI > held OI at previous close | E18: =B257 -> 45524 | F18: =C257 -> 45555 | G18: =D257 -> 10 | H18: =IF(H256,E256,SUMIFS('Futures Data'!$E$5:$E$3471,'Futures Data'!$A$5:$A$3471,A257,'Futures Data'!$B$5:$B$3471,B257)) -> 22955 | I18: =IF(H256,G256,E257) -> 24380 | J18: =J257 -> 6193 | K18: =K257 -> 6260 | L18: =L257 -> 67 | M18: =L257/J257 -> 0.010818666 | N18: =A258 -> 45510
A19: 12 | B19: =IF(H278,A278,A279) -> 45539 | C19: =A279 -> 45540 | D19: =IF(H278,"OI signal: next-month OI > held OI at previous close","Calendar backstop: "&D279&" trading days left") -> OI signal: next-month OI > held OI at previous close | E19: =B279 -> 45555 | F19: =C279 -> 45583 | G19: =D279 -> 11 | H19: =IF(H278,E278,SUMIFS('Futures Data'!$E$5:$E$3471,'Futures Data'!$A$5:$A$3471,A279,'Futures Data'!$B$5:$B$3471,B279)) -> 17915 | I19: =IF(H278,G278,E279) -> 23995 | J19: =J279 -> 6108 | K19: =K279 -> 6193 | L19: =L279 -> 85 | M19: =L279/J279 -> 0.013916176 | N19: =A280 -> 45541
A20: 13 | B20: =IF(H298,A298,A299) -> 45568 | C20: =A299 -> 45569 | D20: =IF(H298,"OI signal: next-month OI > held OI at previous close","Calendar backstop: "&D299&" trading days left") -> OI signal: next-month OI > held OI at previous close | E20: =B299 -> 45583 | F20: =C299 -> 45616 | G20: =D299 -> 10 | H20: =IF(H298,E298,SUMIFS('Futures Data'!$E$5:$E$3471,'Futures Data'!$A$5:$A$3471,A299,'Futures Data'!$B$5:$B$3471,B299)) -> 22525 | I20: =IF(H298,G298,E299) -> 28215 | J20: =J299 -> 6819 | K20: =K299 -> 6889 | L20: =L299 -> 70 | M20: =L299/J299 -> 0.010265435 | N20: =A300 -> 45572
A21: 14 | B21: =IF(H317,A317,A318) -> 45595 | C21: =A318 -> 45596 | D21: =IF(H317,"OI signal: next-month OI > held OI at previous close","Calendar backstop: "&D318&" trading days left") -> OI signal: next-month OI > held OI at previous close | E21: =B318 -> 45616 | F21: =C318 -> 45646 | G21: =D318 -> 12 | H21: =IF(H317,E317,SUMIFS('Futures Data'!$E$5:$E$3471,'Futures Data'!$A$5:$A$3471,A318,'Futures Data'!$B$5:$B$3471,B318)) -> 18835 | I21: =IF(H317,G317,E318) -> 20575 | J21: =J318 -> 6603 | K21: =K318 -> 6724 | L21: =L318 -> 121 | M21: =L318/J318 -> 0.018325004 | N21: =A319 -> 45597
A22: 15 | B22: =IF(H343,A343,A344) -> 45635 | C22: =A344 -> 45636 | D22: =IF(H343,"OI signal: next-month OI > held OI at previous close","Calendar backstop: "&D344&" trading days left") -> OI signal: next-month OI > held OI at previous close | E22: =B344 -> 45646 | F22: =C344 -> 45677 | G22: =D344 -> 8 | H22: =IF(H343,E343,SUMIFS('Futures Data'!$E$5:$E$3471,'Futures Data'!$A$5:$A$3471,A344,'Futures Data'!$B$5:$B$3471,B344)) -> 13170 | I22: =IF(H343,G343,E344) -> 16915 | J22: =J344 -> 6294 | K22: =K344 -> 6368 | L22: =L344 -> 74 | M22: =L344/J344 -> 0.011757229 | N22: =A345 -> 45637
A23: 16 | B23: =IF(H364,A364,A365) -> 45665 | C23: =A365 -> 45666 | D23: =IF(H364,"OI signal: next-month OI > held OI at previous close","Calendar backstop: "&D365&" trading days left") -> OI signal: next-month OI > held OI at previous close | E23: =B365 -> 45677 | F23: =C365 -> 45708 | G23: =D365 -> 7 | H23: =IF(H364,E364,SUMIFS('Futures Data'!$E$5:$E$3471,'Futures Data'!$A$5:$A$3471,A365,'Futures Data'!$B$5:$B$3471,B365)) -> 13065 | I23: =IF(H364,G364,E365) -> 13230 | J23: =J365 -> 6318 | K23: =K365 -> 6368 | L23: =L365 -> 50 | M23: =L365/J365 -> 0.0079138968 | N23: =A366 -> 45667
A24: 17 | B24: =IF(H388,A388,A389) -> 45698 | C24: =A389 -> 45699 | D24: =IF(H388,"OI signal: next-month OI > held OI at previous close","Calendar backstop: "&D389&" trading days left") -> OI signal: next-month OI > held OI at previous close | E24: =B389 -> 45708 | F24: =C389 -> 45736 | G24: =D389 -> 7 | H24: =IF(H388,E388,SUMIFS('Futures Data'!$E$5:$E$3471,'Futures Data'!$A$5:$A$3471,A389,'Futures Data'!$B$5:$B$3471,B389)) -> 15180 | I24: =IF(H388,G388,E389) -> 16360 | J24: =J389 -> 6543 | K24: =K389 -> 6290 | L24: =L389 -> -253 | M24: =L389/J389 -> -0.038667278 | N24: =A390 -> 45700
A25: 18 | B25: =IF(H406,A406,A407) -> 45726 | C25: =A407 -> 45726 | D25: =IF(H406,"OI signal: next-month OI > held OI at previous close","Calendar backstop: "&D407&" trading days left") -> Calendar backstop: 7 trading days left | E25: =B407 -> 45736 | F25: =C407 -> 45764 | G25: =D407 -> 7 | H25: =IF(H406,E406,SUMIFS('Futures Data'!$E$5:$E$3471,'Futures Data'!$A$5:$A$3471,A407,'Futures Data'!$B$5:$B$3471,B407)) -> 20320 | I25: =IF(H406,G406,E407) -> 13095 | J25: =J407 -> 6256 | K25: =K407 -> 6264 | L25: =L407 -> 8 | M25: =L407/J407 -> 0.0012787724 | N25: =A408 -> 45727
A26: 19 | B26: =IF(H417,A417,A418) -> 45741 | C26: =A418 -> 45742 | D26: =IF(H417,"OI signal: next-month OI > held OI at previous close","Calendar backstop: "&D418&" trading days left") -> OI signal: next-month OI > held OI at previous close | E26: =B418 -> 45764 | F26: =C418 -> 45797 | G26: =D418 -> 13 | H26: =IF(H417,E417,SUMIFS('Futures Data'!$E$5:$E$3471,'Futures Data'!$A$5:$A$3471,A418,'Futures Data'!$B$5:$B$3471,B418)) -> 13800 | I26: =IF(H417,G417,E418) -> 14885 | J26: =J418 -> 6272 | K26: =K418 -> 6340 | L26: =L418 -> 68 | M26: =L418/J418 -> 0.010841837 | N26: =A419 -> 45743
A27: 20 | B27: =IF(H437,A437,A438) -> 45775 | C27: =A438 -> 45776 | D27: =IF(H437,"OI signal: next-month OI > held OI at previous close","Calendar backstop: "&D438&" trading days left") -> OI signal: next-month OI > held OI at previous close | E27: =B438 -> 45797 | F27: =C438 -> 45828 | G27: =D438 -> 14 | H27: =IF(H437,E437,SUMIFS('Futures Data'!$E$5:$E$3471,'Futures Data'!$A$5:$A$3471,A438,'Futures Data'!$B$5:$B$3471,B438)) -> 17560 | I27: =IF(H437,G437,E438) -> 18605 | J27: =J438 -> 6261 | K27: =K438 -> 6326 | L27: =L438 -> 65 | M27: =L438/J438 -> 0.010381728 | N27: =A439 -> 45777
A28: 21 | B28: =IF(H462,A462,A463) -> 45811 | C28: =A463 -> 45812 | D28: =IF(H462,"OI signal: next-month OI > held OI at previous close","Calendar backstop: "&D463&" trading days left") -> OI signal: next-month OI > held OI at previous close | E28: =B463 -> 45828 | F28: =C463 -> 45856 | G28: =D463 -> 12 | H28: =IF(H462,E462,SUMIFS('Futures Data'!$E$5:$E$3471,'Futures Data'!$A$5:$A$3471,A463,'Futures Data'!$B$5:$B$3471,B463)) -> 18280 | I28: =IF(H462,G462,E463) -> 19515 | J28: =J463 -> 6392 | K28: =K463 -> 6470 | L28: =L463 -> 78 | M28: =L463/J463 -> 0.012202753 | N28: =A464 -> 45813
A29: 22 | B29: =IF(H482,A482,A483) -> 45839 | C29: =A483 -> 45840 | D29: =IF(H482,"OI signal: next-month OI > held OI at previous close","Calendar backstop: "&D483&" trading days left") -> OI signal: next-month OI > held OI at previous close | E29: =B483 -> 45856 | F29: =C483 -> 45889 | G29: =D483 -> 12 | H29: =IF(H482,E482,SUMIFS('Futures Data'!$E$5:$E$3471,'Futures Data'!$A$5:$A$3471,A483,'Futures Data'!$B$5:$B$3471,B483)) -> 21870 | I29: =IF(H482,G482,E483) -> 23290 | J29: =J483 -> 6898 | K29: =K483 -> 6974 | L29: =L483 -> 76 | M29: =L483/J483 -> 0.011017686 | N29: =A484 -> 45841
A30: 23 | B30: =IF(H508,A508,A509) -> 45875 | C30: =A509 -> 45876 | D30: =IF(H508,"OI signal: next-month OI > held OI at previous close","Calendar backstop: "&D509&" trading days left") -> OI signal: next-month OI > held OI at previous close | E30: =B509 -> 45889 | F30: =C509 -> 45919 | G30: =D509 -> 8 | H30: =IF(H508,E508,SUMIFS('Futures Data'!$E$5:$E$3471,'Futures Data'!$A$5:$A$3471,A509,'Futures Data'!$B$5:$B$3471,B509)) -> 21840 | I30: =IF(H508,G508,E509) -> 22505 | J30: =J509 -> 6638 | K30: =K509 -> 6704 | L30: =L509 -> 66 | M30: =L509/J509 -> 0.0099427538 | N30: =A510 -> 45877
A31: 24 | B31: =IF(H526,A526,A527) -> 45903 | C31: =A527 -> 45904 | D31: =IF(H526,"OI signal: next-month OI > held OI at previous close","Calendar backstop: "&D527&" trading days left") -> OI signal: next-month OI > held OI at previous close | E31: =B527 -> 45919 | F31: =C527 -> 45950 | G31: =D527 -> 11 | H31: =IF(H526,E526,SUMIFS('Futures Data'!$E$5:$E$3471,'Futures Data'!$A$5:$A$3471,A527,'Futures Data'!$B$5:$B$3471,B527)) -> 18165 | I31: =IF(H526,G526,E527) -> 18950 | J31: =J527 -> 6622 | K31: =K527 -> 6685 | L31: =L527 -> 63 | M31: =L527/J527 -> 0.0095137421 | N31: =A528 -> 45905
A32: 25 | B32: =IF(H546,A546,A547) -> 45931 | C32: =A547 -> 45933 | D32: =IF(H546,"OI signal: next-month OI > held OI at previous close","Calendar backstop: "&D547&" trading days left") -> OI signal: next-month OI > held OI at previous close | E32: =B547 -> 45950 | F32: =C547 -> 45981 | G32: =D547 -> 11 | H32: =IF(H546,E546,SUMIFS('Futures Data'!$E$5:$E$3471,'Futures Data'!$A$5:$A$3471,A547,'Futures Data'!$B$5:$B$3471,B547)) -> 17630 | I32: =IF(H546,G546,E547) -> 19320 | J32: =J547 -> 6466 | K32: =K547 -> 6542 | L32: =L547 -> 76 | M32: =L547/J547 -> 0.011753789 | N32: =A548 -> 45936
A33: 26 | B33: =IF(H569,A569,A570) -> 45967 | C33: =A570 -> 45968 | D33: =IF(H569,"OI signal: next-month OI > held OI at previous close","Calendar backstop: "&D570&" trading days left") -> OI signal: next-month OI > held OI at previous close | E33: =B570 -> 45981 | F33: =C570 -> 46010 | G33: =D570 -> 9 | H33: =IF(H569,E569,SUMIFS('Futures Data'!$E$5:$E$3471,'Futures Data'!$A$5:$A$3471,A570,'Futures Data'!$B$5:$B$3471,B570)) -> 18525 | I33: =IF(H569,G569,E570) -> 19865 | J33: =J570 -> 6758 | K33: =K570 -> 6829 | L33: =L570 -> 71 | M33: =L570/J570 -> 0.010506067 | N33: =A571 -> 45971
A34: 27 | B34: =IF(H590,A590,A591) -> 45996 | C34: =A591 -> 45999 | D34: =IF(H590,"OI signal: next-month OI > held OI at previous close","Calendar backstop: "&D591&" trading days left") -> OI signal: next-month OI > held OI at previous close | E34: =B591 -> 46010 | F34: =C591 -> 46042 | G34: =D591 -> 9 | H34: =IF(H590,E590,SUMIFS('Futures Data'!$E$5:$E$3471,'Futures Data'!$A$5:$A$3471,A591,'Futures Data'!$B$5:$B$3471,B591)) -> 13785 | I34: =IF(H590,G590,E591) -> 15585 | J34: =J591 -> 6958 | K34: =K591 -> 6984 | L34: =L591 -> 26 | M34: =L591/J591 -> 0.0037367059 | N34: =A592 -> 46000
A35: 28 | B35: =IF(H612,A612,A613) -> 46030 | C35: =A613 -> 46030 | D35: =IF(H612,"OI signal: next-month OI > held OI at previous close","Calendar backstop: "&D613&" trading days left") -> Calendar backstop: 7 trading days left | E35: =B613 -> 46042 | F35: =C613 -> 46073 | G35: =D613 -> 7 | H35: =IF(H612,E612,SUMIFS('Futures Data'!$E$5:$E$3471,'Futures Data'!$A$5:$A$3471,A613,'Futures Data'!$B$5:$B$3471,B613)) -> 12415 | I35: =IF(H612,G612,E613) -> 14460 | J35: =J613 -> 6618 | K35: =K613 -> 6667 | L35: =L613 -> 49 | M35: =L613/J613 -> 0.0074040496 | N35: =A614 -> 46031
A36: 29 | B36: =IF(H635,A635,A636) -> 46063 | C36: =A636 -> 46064 | D36: =IF(H635,"OI signal: next-month OI > held OI at previous close","Calendar backstop: "&D636&" trading days left") -> OI signal: next-month OI > held OI at previous close | E36: =B636 -> 46073 | F36: =C636 -> 46101 | G36: =D636 -> 7 | H36: =IF(H635,E635,SUMIFS('Futures Data'!$E$5:$E$3471,'Futures Data'!$A$5:$A$3471,A636,'Futures Data'!$B$5:$B$3471,B636)) -> 14365 | I36: =IF(H635,G635,E636) -> 15970 | J36: =J636 -> 6388 | K36: =K636 -> 6445 | L36: =L636 -> 57 | M36: =L636/J636 -> 0.0089229806 | N36: =A637 -> 46065
A37: 30 | B37: =IF(H651,A651,A652) -> 46086 | C37: =A652 -> 46087 | D37: =IF(H651,"OI signal: next-month OI > held OI at previous close","Calendar backstop: "&D652&" trading days left") -> OI signal: next-month OI > held OI at previous close | E37: =B652 -> 46101 | F37: =C652 -> 46132 | G37: =D652 -> 10 | H37: =IF(H651,E651,SUMIFS('Futures Data'!$E$5:$E$3471,'Futures Data'!$A$5:$A$3471,A652,'Futures Data'!$B$5:$B$3471,B652)) -> 14625 | I37: =IF(H651,G651,E652) -> 15370 | J37: =J652 -> 6277 | K37: =K652 -> 6322 | L37: =L652 -> 45 | M37: =L652/J652 -> 0.0071690298 | N37: =A653 -> 46090
A38: 31 | B38: =IF(H671,A671,A672) -> 46119 | C38: =A672 -> 46120 | D38: =IF(H671,"OI signal: next-month OI > held OI at previous close","Calendar backstop: "&D672&" trading days left") -> OI signal: next-month OI > held OI at previous close | E38: =B672 -> 46132 | F38: =C672 -> 46162 | G38: =D672 -> 7 | H38: =IF(H671,E671,SUMIFS('Futures Data'!$E$5:$E$3471,'Futures Data'!$A$5:$A$3471,A672,'Futures Data'!$B$5:$B$3471,B672)) -> 14985 | I38: =IF(H671,G671,E672) -> 16660 | J38: =J672 -> 6375 | K38: =K672 -> 6441 | L38: =L672 -> 66 | M38: =L672/J672 -> 0.010352941 | N38: =A673 -> 46121
A39: 32 | B39: =IF(H690,A690,A691) -> 46148 | C39: =A691 -> 46149 | D39: =IF(H690,"OI signal: next-month OI > held OI at previous close","Calendar backstop: "&D691&" trading days left") -> OI signal: next-month OI > held OI at previous close | E39: =B691 -> 46162 | F39: =C691 -> 46192 | G39: =D691 -> 9 | H39: =IF(H690,E690,SUMIFS('Futures Data'!$E$5:$E$3471,'Futures Data'!$A$5:$A$3471,A691,'Futures Data'!$B$5:$B$3471,B691)) -> 14275 | I39: =IF(H690,G690,E691) -> 17020 | J39: =J691 -> 6501 | K39: =K691 -> 6592 | L39: =L691 -> 91 | M39: =L691/J691 -> 0.013997846 | N39: =A692 -> 46150
A40: 33 | B40: =IF(H713,A713,A714) -> 46182 | C40: =A714 -> 46183 | D40: =IF(H713,"OI signal: next-month OI > held OI at previous close","Calendar backstop: "&D714&" trading days left") -> OI signal: next-month OI > held OI at previous close | E40: =B714 -> 46192 | F40: =C714 -> 46223 | G40: =D714 -> 7 | H40: =IF(H713,E713,SUMIFS('Futures Data'!$E$5:$E$3471,'Futures Data'!$A$5:$A$3471,A714,'Futures Data'!$B$5:$B$3471,B714)) -> 15780 | I40: =IF(H713,G713,E714) -> 17960 | J40: =J714 -> 6549 | K40: =K714 -> 6656 | L40: =L714 -> 107 | M40: =L714/J714 -> 0.016338372 | N40: =A715 -> 46184
A41: 34 | B41: =IF(H731,A731,A732) -> 46209 | C41: =A732 -> 46210 | D41: =IF(H731,"OI signal: next-month OI > held OI at previous close","Calendar backstop: "&D732&" trading days left") -> OI signal: next-month OI > held OI at previous close | E41: =B732 -> 46223 | F41: =C732 -> 46254 | G41: =D732 -> 9 | H41: =IF(H731,E731,SUMIFS('Futures Data'!$E$5:$E$3471,'Futures Data'!$A$5:$A$3471,A732,'Futures Data'!$B$5:$B$3471,B732)) -> 20145 | I41: =IF(H731,G731,E732) -> 21375 | J41: =J732 -> 7042 | K41: =K732 -> 7125 | L41: =L732 -> 83 | M41: =L732/J732 -> 0.011786424 | N41: =A733 -> 46211
...

Sheet Daily Analysis
A1: Daily Analysis: matched one-day returns (consecutive NCDEX trading days with an SEA quote on both days)
A2: rA = LN(meal_t / meal_t-1); rF = LN(F_t / F_t-1) using the SAME contract on both days (column E). Hedged return = rA - h x rF (Buyukkara et al. eq. 12). Nothing is interpolated or carried forward.
A4: Date t | B4: Previous NCDEX trading day | C4: Castor meal t-1 (Rs/MT) | D4: Castor meal t (Rs/MT) | E4: Contract held over (t-1,t] | F4: Futures close t-1 (Rs/qtl) | G4: Futures close t (Rs/qtl) | H4: rA castor meal return | I4: rF futures return | J4: Sample | K4: Hedged: OLS h* | L4: Hedged: naive h = 1 | M4: GARCH h_t (Python, one-step-ahead) | N4: Hedged: GARCH h_t | O4: OLS h* (for chart)
A5: ='Roll Schedule'!A48 -> 45195 | B5: ='Roll Schedule'!A47 -> 45194 | C5: =SUMIFS('Spot Data'!$E$5:$E$651,'Spot Data'!$A$5:$A$651,B5,'Spot Data'!$H$5:$H$651,"YES") -> 9575 | D5: =SUMIFS('Spot Data'!$E$5:$E$651,'Spot Data'!$A$5:$A$651,A5,'Spot Data'!$H$5:$H$651,"YES") -> 9500 | E5: ='Roll Schedule'!B48 -> 45219 | F5: =SUMIFS('Futures Data'!$C$5:$C$3471,'Futures Data'!$A$5:$A$3471,B5,'Futures Data'!$B$5:$B$3471,E5) -> 6176 | G5: =SUMIFS('Futures Data'!$C$5:$C$3471,'Futures Data'!$A$5:$A$3471,A5,'Futures Data'!$B$5:$B$3471,E5) -> 6155 | H5: =LN(D5/C5) -> -0.0078637365 | I5: =LN(G5/F5) -> -0.0034060531 | J5: =IF(A5<='Results & Charts'!$C$5,"In-sample","Out-of-sample") -> In-sample | K5: =H5-'Results & Charts'!$C$9*I5 -> -0.0057738934 | L5: =H5-I5 -> -0.0044576834 | M5: 0.61356738 | N5: =H5-M5*I5 -> -0.0057738934 | O5: ='Results & Charts'!$C$9 -> 0.61356738
A6: ='Roll Schedule'!A52 -> 45202 | B6: ='Roll Schedule'!A51 -> 45198 | C6: =SUMIFS('Spot Data'!$E$5:$E$651,'Spot Data'!$A$5:$A$651,B6,'Spot Data'!$H$5:$H$651,"YES") -> 9450 | D6: =SUMIFS('Spot Data'!$E$5:$E$651,'Spot Data'!$A$5:$A$651,A6,'Spot Data'!$H$5:$H$651,"YES") -> 9350 | E6: ='Roll Schedule'!B52 -> 45219 | F6: =SUMIFS('Futures Data'!$C$5:$C$3471,'Futures Data'!$A$5:$A$3471,B6,'Futures Data'!$B$5:$B$3471,E6) -> 6137 | G6: =SUMIFS('Futures Data'!$C$5:$C$3471,'Futures Data'!$A$5:$A$3471,A6,'Futures Data'!$B$5:$B$3471,E6) -> 6101 | H6: =LN(D6/C6) -> -0.010638398 | I6: =LN(G6/F6) -> -0.0058833312 | J6: =IF(A6<='Results & Charts'!$C$5,"In-sample","Out-of-sample") -> In-sample | K6: =H6-'Results & Charts'!$C$9*I6 -> -0.0070285781 | L6: =H6-I6 -> -0.004755067 | M6: 0.65175501 | N6: =H6-M6*I6 -> -0.0068039076 | O6: ='Results & Charts'!$C$9 -> 0.61356738
A7: ='Roll Schedule'!A53 -> 45203 | B7: ='Roll Schedule'!A52 -> 45202 | C7: =SUMIFS('Spot Data'!$E$5:$E$651,'Spot Data'!$A$5:$A$651,B7,'Spot Data'!$H$5:$H$651,"YES") -> 9350 | D7: =SUMIFS('Spot Data'!$E$5:$E$651,'Spot Data'!$A$5:$A$651,A7,'Spot Data'!$H$5:$H$651,"YES") -> 9150 | E7: ='Roll Schedule'!B53 -> 45219 | F7: =SUMIFS('Futures Data'!$C$5:$C$3471,'Futures Data'!$A$5:$A$3471,B7,'Futures Data'!$B$5:$B$3471,E7) -> 6101 | G7: =SUMIFS('Futures Data'!$C$5:$C$3471,'Futures Data'!$A$5:$A$3471,A7,'Futures Data'!$B$5:$B$3471,E7) -> 6135 | H7: =LN(D7/C7) -> -0.021622464 | I7: =LN(G7/F7) -> 0.005557386 | J7: =IF(A7<='Results & Charts'!$C$5,"In-sample","Out-of-sample") -> In-sample | K7: =H7-'Results & Charts'!$C$9*I7 -> -0.025032295 | L7: =H7-I7 -> -0.02717985 | M7: 0.67065402 | N7: =H7-M7*I7 -> -0.025349547 | O7: ='Results & Charts'!$C$9 -> 0.61356738
A8: ='Roll Schedule'!A54 -> 45204 | B8: ='Roll Schedule'!A53 -> 45203 | C8: =SUMIFS('Spot Data'!$E$5:$E$651,'Spot Data'!$A$5:$A$651,B8,'Spot Data'!$H$5:$H$651,"YES") -> 9150 | D8: =SUMIFS('Spot Data'!$E$5:$E$651,'Spot Data'!$A$5:$A$651,A8,'Spot Data'!$H$5:$H$651,"YES") -> 9000 | E8: ='Roll Schedule'!B54 -> 45250 | F8: =SUMIFS('Futures Data'!$C$5:$C$3471,'Futures Data'!$A$5:$A$3471,B8,'Futures Data'!$B$5:$B$3471,E8) -> 6193 | G8: =SUMIFS('Futures Data'!$C$5:$C$3471,'Futures Data'!$A$5:$A$3471,A8,'Futures Data'!$B$5:$B$3471,E8) -> 6175 | H8: =LN(D8/C8) -> -0.016529302 | I8: =LN(G8/F8) -> -0.0029107394 | J8: =IF(A8<='Results & Charts'!$C$5,"In-sample","Out-of-sample") -> In-sample | K8: =H8-'Results & Charts'!$C$9*I8 -> -0.014743367 | L8: =H8-I8 -> -0.013618563 | M8: 0.61635836 | N8: =H8-M8*I8 -> -0.014735243 | O8: ='Results & Charts'!$C$9 -> 0.61356738
A9: ='Roll Schedule'!A55 -> 45205 | B9: ='Roll Schedule'!A54 -> 45204 | C9: =SUMIFS('Spot Data'!$E$5:$E$651,'Spot Data'!$A$5:$A$651,B9,'Spot Data'!$H$5:$H$651,"YES") -> 9000 | D9: =SUMIFS('Spot Data'!$E$5:$E$651,'Spot Data'!$A$5:$A$651,A9,'Spot Data'!$H$5:$H$651,"YES") -> 8950 | E9: ='Roll Schedule'!B55 -> 45250 | F9: =SUMIFS('Futures Data'!$C$5:$C$3471,'Futures Data'!$A$5:$A$3471,B9,'Futures Data'!$B$5:$B$3471,E9) -> 6175 | G9: =SUMIFS('Futures Data'!$C$5:$C$3471,'Futures Data'!$A$5:$A$3471,A9,'Futures Data'!$B$5:$B$3471,E9) -> 6162 | H9: =LN(D9/C9) -> -0.005571045 | I9: =LN(G9/F9) -> -0.0021074823 | J9: =IF(A9<='Results & Charts'!$C$5,"In-sample","Out-of-sample") -> In-sample | K9: =H9-'Results & Charts'!$C$9*I9 -> -0.0042779626 | L9: =H9-I9 -> -0.0034635627 | M9: 0.65994759 | N9: =H9-M9*I9 -> -0.0041802172 | O9: ='Results & Charts'!$C$9 -> 0.61356738
A10: ='Roll Schedule'!A56 -> 45208 | B10: ='Roll Schedule'!A55 -> 45205 | C10: =SUMIFS('Spot Data'!$E$5:$E$651,'Spot Data'!$A$5:$A$651,B10,'Spot Data'!$H$5:$H$651,"YES") -> 8950 | D10: =SUMIFS('Spot Data'!$E$5:$E$651,'Spot Data'!$A$5:$A$651,A10,'Spot Data'!$H$5:$H$651,"YES") -> 8875 | E10: ='Roll Schedule'!B56 -> 45250 | F10: =SUMIFS('Futures Data'!$C$5:$C$3471,'Futures Data'!$A$5:$A$3471,B10,'Futures Data'!$B$5:$B$3471,E10) -> 6162 | G10: =SUMIFS('Futures Data'!$C$5:$C$3471,'Futures Data'!$A$5:$A$3471,A10,'Futures Data'!$B$5:$B$3471,E10) -> 6115 | H10: =LN(D10/C10) -> -0.0084151969 | I10: =LN(G10/F10) -> -0.007656631 | J10: =IF(A10<='Results & Charts'!$C$5,"In-sample","Out-of-sample") -> In-sample | K10: =H10-'Results & Charts'!$C$9*I10 -> -0.0037173379 | L10: =H10-I10 -> -0.00075856589 | M10: 0.69390476 | N10: =H10-M10*I10 -> -0.0031022242 | O10: ='Results & Charts'!$C$9 -> 0.61356738
A11: ='Roll Schedule'!A57 -> 45209 | B11: ='Roll Schedule'!A56 -> 45208 | C11: =SUMIFS('Spot Data'!$E$5:$E$651,'Spot Data'!$A$5:$A$651,B11,'Spot Data'!$H$5:$H$651,"YES") -> 8875 | D11: =SUMIFS('Spot Data'!$E$5:$E$651,'Spot Data'!$A$5:$A$651,A11,'Spot Data'!$H$5:$H$651,"YES") -> 8950 | E11: ='Roll Schedule'!B57 -> 45250 | F11: =SUMIFS('Futures Data'!$C$5:$C$3471,'Futures Data'!$A$5:$A$3471,B11,'Futures Data'!$B$5:$B$3471,E11) -> 6115 | G11: =SUMIFS('Futures Data'!$C$5:$C$3471,'Futures Data'!$A$5:$A$3471,A11,'Futures Data'!$B$5:$B$3471,E11) -> 6124 | H11: =LN(D11/C11) -> 0.0084151969 | I11: =LN(G11/F11) -> 0.0014707087 | J11: =IF(A11<='Results & Charts'!$C$5,"In-sample","Out-of-sample") -> In-sample | K11: =H11-'Results & Charts'!$C$9*I11 -> 0.0075128181 | L11: =H11-I11 -> 0.0069444883 | M11: 0.66582879 | N11: =H11-M11*I11 -> 0.0074359568 | O11: ='Results & Charts'!$C$9 -> 0.61356738
A12: ='Roll Schedule'!A58 -> 45210 | B12: ='Roll Schedule'!A57 -> 45209 | C12: =SUMIFS('Spot Data'!$E$5:$E$651,'Spot Data'!$A$5:$A$651,B12,'Spot Data'!$H$5:$H$651,"YES") -> 8950 | D12: =SUMIFS('Spot Data'!$E$5:$E$651,'Spot Data'!$A$5:$A$651,A12,'Spot Data'!$H$5:$H$651,"YES") -> 8800 | E12: ='Roll Schedule'!B58 -> 45250 | F12: =SUMIFS('Futures Data'!$C$5:$C$3471,'Futures Data'!$A$5:$A$3471,B12,'Futures Data'!$B$5:$B$3471,E12) -> 6124 | G12: =SUMIFS('Futures Data'!$C$5:$C$3471,'Futures Data'!$A$5:$A$3471,A12,'Futures Data'!$B$5:$B$3471,E12) -> 6072 | H12: =LN(D12/C12) -> -0.016901811 | I12: =LN(G12/F12) -> -0.0085274377 | J12: =IF(A12<='Results & Charts'!$C$5,"In-sample","Out-of-sample") -> In-sample | K12: =H12-'Results & Charts'!$C$9*I12 -> -0.011669653 | L12: =H12-I12 -> -0.0083743731 | M12: 0.70167923 | N12: =H12-M12*I12 -> -0.010918285 | O12: ='Results & Charts'!$C$9 -> 0.61356738
A13: ='Roll Schedule'!A59 -> 45211 | B13: ='Roll Schedule'!A58 -> 45210 | C13: =SUMIFS('Spot Data'!$E$5:$E$651,'Spot Data'!$A$5:$A$651,B13,'Spot Data'!$H$5:$H$651,"YES") -> 8800 | D13: =SUMIFS('Spot Data'!$E$5:$E$651,'Spot Data'!$A$5:$A$651,A13,'Spot Data'!$H$5:$H$651,"YES") -> 8700 | E13: ='Roll Schedule'!B59 -> 45250 | F13: =SUMIFS('Futures Data'!$C$5:$C$3471,'Futures Data'!$A$5:$A$3471,B13,'Futures Data'!$B$5:$B$3471,E13) -> 6072 | G13: =SUMIFS('Futures Data'!$C$5:$C$3471,'Futures Data'!$A$5:$A$3471,A13,'Futures Data'!$B$5:$B$3471,E13) -> 6034 | H13: =LN(D13/C13) -> -0.011428696 | I13: =LN(G13/F13) -> -0.0062778994 | J13: =IF(A13<='Results & Charts'!$C$5,"In-sample","Out-of-sample") -> In-sample | K13: =H13-'Results & Charts'!$C$9*I13 -> -0.0075767815 | L13: =H13-I13 -> -0.0051507965 | M13: 0.68142864 | N13: =H13-M13*I13 -> -0.0071507554 | O13: ='Results & Charts'!$C$9 -> 0.61356738
A14: ='Roll Schedule'!A60 -> 45212 | B14: ='Roll Schedule'!A59 -> 45211 | C14: =SUMIFS('Spot Data'!$E$5:$E$651,'Spot Data'!$A$5:$A$651,B14,'Spot Data'!$H$5:$H$651,"YES") -> 8700 | D14: =SUMIFS('Spot Data'!$E$5:$E$651,'Spot Data'!$A$5:$A$651,A14,'Spot Data'!$H$5:$H$651,"YES") -> 8700 | E14: ='Roll Schedule'!B60 -> 45250 | F14: =SUMIFS('Futures Data'!$C$5:$C$3471,'Futures Data'!$A$5:$A$3471,B14,'Futures Data'!$B$5:$B$3471,E14) -> 6034 | G14: =SUMIFS('Futures Data'!$C$5:$C$3471,'Futures Data'!$A$5:$A$3471,A14,'Futures Data'!$B$5:$B$3471,E14) -> 6035 | H14: =LN(D14/C14) -> 0 | I14: =LN(G14/F14) -> 0.00016571381 | J14: =IF(A14<='Results & Charts'!$C$5,"In-sample","Out-of-sample") -> In-sample | K14: =H14-'Results & Charts'!$C$9*I14 -> -0.00010167659 | L14: =H14-I14 -> -0.00016571381 | M14: 0.68945143 | N14: =H14-M14*I14 -> -0.00011425162 | O14: ='Results & Charts'!$C$9 -> 0.61356738
A15: ='Roll Schedule'!A61 -> 45215 | B15: ='Roll Schedule'!A60 -> 45212 | C15: =SUMIFS('Spot Data'!$E$5:$E$651,'Spot Data'!$A$5:$A$651,B15,'Spot Data'!$H$5:$H$651,"YES") -> 8700 | D15: =SUMIFS('Spot Data'!$E$5:$E$651,'Spot Data'!$A$5:$A$651,A15,'Spot Data'!$H$5:$H$651,"YES") -> 8650 | E15: ='Roll Schedule'!B61 -> 45250 | F15: =SUMIFS('Futures Data'!$C$5:$C$3471,'Futures Data'!$A$5:$A$3471,B15,'Futures Data'!$B$5:$B$3471,E15) -> 6035 | G15: =SUMIFS('Futures Data'!$C$5:$C$3471,'Futures Data'!$A$5:$A$3471,A15,'Futures Data'!$B$5:$B$3471,E15) -> 6079 | H15: =LN(D15/C15) -> -0.0057637047 | I15: =LN(G15/F15) -> 0.0072643542 | J15: =IF(A15<='Results & Charts'!$C$5,"In-sample","Out-of-sample") -> In-sample | K15: =H15-'Results & Charts'!$C$9*I15 -> -0.010220876 | L15: =H15-I15 -> -0.013028059 | M15: 0.72549104 | N15: =H15-M15*I15 -> -0.011033929 | O15: ='Results & Charts'!$C$9 -> 0.61356738
A16: ='Roll Schedule'!A64 -> 45218 | B16: ='Roll Schedule'!A63 -> 45217 | C16: =SUMIFS('Spot Data'!$E$5:$E$651,'Spot Data'!$A$5:$A$651,B16,'Spot Data'!$H$5:$H$651,"YES") -> 8600 | D16: =SUMIFS('Spot Data'!$E$5:$E$651,'Spot Data'!$A$5:$A$651,A16,'Spot Data'!$H$5:$H$651,"YES") -> 8550 | E16: ='Roll Schedule'!B64 -> 45250 | F16: =SUMIFS('Futures Data'!$C$5:$C$3471,'Futures Data'!$A$5:$A$3471,B16,'Futures Data'!$B$5:$B$3471,E16) -> 6009 | G16: =SUMIFS('Futures Data'!$C$5:$C$3471,'Futures Data'!$A$5:$A$3471,A16,'Futures Data'!$B$5:$B$3471,E16) -> 6006 | H16: =LN(D16/C16) -> -0.0058309203 | I16: =LN(G16/F16) -> -0.00049937579 | J16: =IF(A16<='Results & Charts'!$C$5,"In-sample","Out-of-sample") -> In-sample | K16: =H16-'Results & Charts'!$C$9*I16 -> -0.0055245196 | L16: =H16-I16 -> -0.0053315445 | M16: 0.64911584 | N16: =H16-M16*I16 -> -0.0055067676 | O16: ='Results & Charts'!$C$9 -> 0.61356738
A17: ='Roll Schedule'!A65 -> 45219 | B17: ='Roll Schedule'!A64 -> 45218 | C17: =SUMIFS('Spot Data'!$E$5:$E$651,'Spot Data'!$A$5:$A$651,B17,'Spot Data'!$H$5:$H$651,"YES") -> 8550 | D17: =SUMIFS('Spot Data'!$E$5:$E$651,'Spot Data'!$A$5:$A$651,A17,'Spot Data'!$H$5:$H$651,"YES") -> 8450 | E17: ='Roll Schedule'!B65 -> 45250 | F17: =SUMIFS('Futures Data'!$C$5:$C$3471,'Futures Data'!$A$5:$A$3471,B17,'Futures Data'!$B$5:$B$3471,E17) -> 6006 | G17: =SUMIFS('Futures Data'!$C$5:$C$3471,'Futures Data'!$A$5:$A$3471,A17,'Futures Data'!$B$5:$B$3471,E17) -> 6036 | H17: =LN(D17/C17) -> -0.011764842 | I17: =LN(G17/F17) -> 0.0049825713 | J17: =IF(A17<='Results & Charts'!$C$5,"In-sample","Out-of-sample") -> In-sample | K17: =H17-'Results & Charts'!$C$9*I17 -> -0.014821985 | L17: =H17-I17 -> -0.016747413 | M17: 0.68388585 | N17: =H17-M17*I17 -> -0.015172352 | O17: ='Results & Charts'!$C$9 -> 0.61356738
A18: ='Roll Schedule'!A66 -> 45222 | B18: ='Roll Schedule'!A65 -> 45219 | C18: =SUMIFS('Spot Data'!$E$5:$E$651,'Spot Data'!$A$5:$A$651,B18,'Spot Data'!$H$5:$H$651,"YES") -> 8450 | D18: =SUMIFS('Spot Data'!$E$5:$E$651,'Spot Data'!$A$5:$A$651,A18,'Spot Data'!$H$5:$H$651,"YES") -> 8450 | E18: ='Roll Schedule'!B66 -> 45250 | F18: =SUMIFS('Futures Data'!$C$5:$C$3471,'Futures Data'!$A$5:$A$3471,B18,'Futures Data'!$B$5:$B$3471,E18) -> 6036 | G18: =SUMIFS('Futures Data'!$C$5:$C$3471,'Futures Data'!$A$5:$A$3471,A18,'Futures Data'!$B$5:$B$3471,E18) -> 6036 | H18: =LN(D18/C18) -> 0 | I18: =LN(G18/F18) -> 0 | J18: =IF(A18<='Results & Charts'!$C$5,"In-sample","Out-of-sample") -> In-sample | K18: =H18-'Results & Charts'!$C$9*I18 -> 0 | L18: =H18-I18 -> 0 | M18: 0.64347098 | N18: =H18-M18*I18 -> 0 | O18: ='Results & Charts'!$C$9 -> 0.61356738
A19: ='Roll Schedule'!A67 -> 45224 | B19: ='Roll Schedule'!A66 -> 45222 | C19: =SUMIFS('Spot Data'!$E$5:$E$651,'Spot Data'!$A$5:$A$651,B19,'Spot Data'!$H$5:$H$651,"YES") -> 8450 | D19: =SUMIFS('Spot Data'!$E$5:$E$651,'Spot Data'!$A$5:$A$651,A19,'Spot Data'!$H$5:$H$651,"YES") -> 8400 | E19: ='Roll Schedule'!B67 -> 45250 | F19: =SUMIFS('Futures Data'!$C$5:$C$3471,'Futures Data'!$A$5:$A$3471,B19,'Futures Data'!$B$5:$B$3471,E19) -> 6036 | G19: =SUMIFS('Futures Data'!$C$5:$C$3471,'Futures Data'!$A$5:$A$3471,A19,'Futures Data'!$B$5:$B$3471,E19) -> 6055 | H19: =LN(D19/C19) -> -0.0059347355 | I19: =LN(G19/F19) -> 0.0031428361 | J19: =IF(A19<='Results & Charts'!$C$5,"In-sample","Out-of-sample") -> In-sample | K19: =H19-'Results & Charts'!$C$9*I19 -> -0.0078630772 | L19: =H19-I19 -> -0.0090775716 | M19: 0.67358418 | N19: =H19-M19*I19 -> -0.0080517002 | O19: ='Results & Charts'!$C$9 -> 0.61356738
A20: ='Roll Schedule'!A68 -> 45225 | B20: ='Roll Schedule'!A67 -> 45224 | C20: =SUMIFS('Spot Data'!$E$5:$E$651,'Spot Data'!$A$5:$A$651,B20,'Spot Data'!$H$5:$H$651,"YES") -> 8400 | D20: =SUMIFS('Spot Data'!$E$5:$E$651,'Spot Data'!$A$5:$A$651,A20,'Spot Data'!$H$5:$H$651,"YES") -> 8150 | E20: ='Roll Schedule'!B68 -> 45250 | F20: =SUMIFS('Futures Data'!$C$5:$C$3471,'Futures Data'!$A$5:$A$3471,B20,'Futures Data'!$B$5:$B$3471,E20) -> 6055 | G20: =SUMIFS('Futures Data'!$C$5:$C$3471,'Futures Data'!$A$5:$A$3471,A20,'Futures Data'!$B$5:$B$3471,E20) -> 6008 | H20: =LN(D20/C20) -> -0.030213779 | I20: =LN(G20/F20) -> -0.0077924625 | J20: =IF(A20<='Results & Charts'!$C$5,"In-sample","Out-of-sample") -> In-sample | K20: =H20-'Results & Charts'!$C$9*I20 -> -0.025432578 | L20: =H20-I20 -> -0.022421316 | M20: 0.67006005 | N20: =H20-M20*I20 -> -0.024992361 | O20: ='Results & Charts'!$C$9 -> 0.61356738
A21: ='Roll Schedule'!A69 -> 45226 | B21: ='Roll Schedule'!A68 -> 45225 | C21: =SUMIFS('Spot Data'!$E$5:$E$651,'Spot Data'!$A$5:$A$651,B21,'Spot Data'!$H$5:$H$651,"YES") -> 8150 | D21: =SUMIFS('Spot Data'!$E$5:$E$651,'Spot Data'!$A$5:$A$651,A21,'Spot Data'!$H$5:$H$651,"YES") -> 8050 | E21: ='Roll Schedule'!B69 -> 45250 | F21: =SUMIFS('Futures Data'!$C$5:$C$3471,'Futures Data'!$A$5:$A$3471,B21,'Futures Data'!$B$5:$B$3471,E21) -> 6008 | G21: =SUMIFS('Futures Data'!$C$5:$C$3471,'Futures Data'!$A$5:$A$3471,A21,'Futures Data'!$B$5:$B$3471,E21) -> 5980 | H21: =LN(D21/C21) -> -0.012345836 | I21: =LN(G21/F21) -> -0.0046713465 | J21: =IF(A21<='Results & Charts'!$C$5,"In-sample","Out-of-sample") -> In-sample | K21: =H21-'Results & Charts'!$C$9*I21 -> -0.00947965 | L21: =H21-I21 -> -0.0076744893 | M21: 0.69830319 | N21: =H21-M21*I21 -> -0.0090838197 | O21: ='Results & Charts'!$C$9 -> 0.61356738
A22: ='Roll Schedule'!A70 -> 45229 | B22: ='Roll Schedule'!A69 -> 45226 | C22: =SUMIFS('Spot Data'!$E$5:$E$651,'Spot Data'!$A$5:$A$651,B22,'Spot Data'!$H$5:$H$651,"YES") -> 8050 | D22: =SUMIFS('Spot Data'!$E$5:$E$651,'Spot Data'!$A$5:$A$651,A22,'Spot Data'!$H$5:$H$651,"YES") -> 7950 | E22: ='Roll Schedule'!B70 -> 45250 | F22: =SUMIFS('Futures Data'!$C$5:$C$3471,'Futures Data'!$A$5:$A$3471,B22,'Futures Data'!$B$5:$B$3471,E22) -> 5980 | G22: =SUMIFS('Futures Data'!$C$5:$C$3471,'Futures Data'!$A$5:$A$3471,A22,'Futures Data'!$B$5:$B$3471,E22) -> 5920 | H22: =LN(D22/C22) -> -0.012500163 | I22: =LN(G22/F22) -> -0.010084119 | J22: =IF(A22<='Results & Charts'!$C$5,"In-sample","Out-of-sample") -> In-sample | K22: =H22-'Results & Charts'!$C$9*I22 -> -0.0063128762 | L22: =H22-I22 -> -0.0024160437 | M22: 0.71892626 | N22: =H22-M22*I22 -> -0.0052504247 | O22: ='Results & Charts'!$C$9 -> 0.61356738
